Traceback (most recent call last):
  File "tf_cnn_benchmarks.py", line 59, in <module>
    app.run(main)  # Raises error on invalid flags, unlike tf.app.run()
  File "/usr/local/lib/python3.6/site-packages/absl/app.py", line 274, in run
    _run_main(main, argv)
  File "/usr/local/lib/python3.6/site-packages/absl/app.py", line 238, in _run_main
    sys.exit(main(argv))
  File "tf_cnn_benchmarks.py", line 48, in main
    bench = benchmark_cnn.BenchmarkCNN(params)
  File "/home/scott/repo/Tensorflow/benchmarks/scripts/tf_cnn_benchmarks/benchmark_cnn.py", line 1085, in __init__
    self.dataset)
  File "/home/scott/repo/Tensorflow/benchmarks/scripts/tf_cnn_benchmarks/models/model_config.py", line 116, in get_model_config
    (model_name, dataset.name))
ValueError: Invalid model name 'densenet40' for dataset 'cifar10'
